Internal Server Error: /update-status/
Traceback (most recent call last):
  File "C:\Users\Windows 11\AppData\Local\Programs\Python\Python310\lib\site-packages\django\db\backends\utils.py", line 89, in _execute
    return self.cursor.execute(sql, params)
  File "C:\Users\Windows 11\AppData\Local\Programs\Python\Python310\lib\site-packages\django\db\backends\sqlite3\base.py", line 328, in execute
    return super().execute(query, params)
sqlite3.IntegrityError: NOT NULL constraint failed: ThesisApp_person.status

The above exception was the direct cause of the following exception:

Traceback (most recent call last):
  File "C:\Users\Windows 11\AppData\Local\Programs\Python\Python310\lib\site-packages\django\core\handlers\exception.py", line 55, in inner
    response = get_response(request)
  File "C:\Users\Windows 11\AppData\Local\Programs\Python\Python310\lib\site-packages\django\core\handlers\base.py", line 197, in _get_response
    response = wrapped_callback(request, *callback_args, **callback_kwargs)
  File "C:\Users\Windows 11\OneDrive\à´Ê¡ì·çÍ»\Coding\Python\Thesis Project\Thesis\ThesisApp\views.py", line 24, in update_status
    all_person.save()
  File "C:\Users\Windows 11\AppData\Local\Programs\Python\Python310\lib\site-packages\django\db\models\base.py", line 814, in save
    self.save_base(
  File "C:\Users\Windows 11\AppData\Local\Programs\Python\Python310\lib\site-packages\django\db\models\base.py", line 877, in save_base
    updated = self._save_table(
  File "C:\Users\Windows 11\AppData\Local\Programs\Python\Python310\lib\site-packages\django\db\models\base.py", line 990, in _save_table
    updated = self._do_update(
  File "C:\Users\Windows 11\AppData\Local\Programs\Python\Python310\lib\site-packages\django\db\models\base.py", line 1054, in _do_update
    return filtered._update(values) > 0
  File "C:\Users\Windows 11\AppData\Local\Programs\Python\Python310\lib\site-packages\django\db\models\query.py", line 1231, in _update
    return query.get_compiler(self.db).execute_sql(CURSOR)
  File "C:\Users\Windows 11\AppData\Local\Programs\Python\Python310\lib\site-packages\django\db\models\sql\compiler.py", line 1984, in execute_sql
    cursor = super().execute_sql(result_type)
  File "C:\Users\Windows 11\AppData\Local\Programs\Python\Python310\lib\site-packages\django\db\models\sql\compiler.py", line 1562, in execute_sql
    cursor.execute(sql, params)
  File "C:\Users\Windows 11\AppData\Local\Programs\Python\Python310\lib\site-packages\django\db\backends\utils.py", line 102, in execute
    return super().execute(sql, params)
  File "C:\Users\Windows 11\AppData\Local\Programs\Python\Python310\lib\site-packages\django\db\backends\utils.py", line 67, in execute
    return self._execute_with_wrappers(
  File "C:\Users\Windows 11\AppData\Local\Programs\Python\Python310\lib\site-packages\django\db\backends\utils.py", line 80, in _execute_with_wrappers
    return executor(sql, params, many, context)
  File "C:\Users\Windows 11\AppData\Local\Programs\Python\Python310\lib\site-packages\django\db\backends\utils.py", line 84, in _execute
    with self.db.wrap_database_errors:
  File "C:\Users\Windows 11\AppData\Local\Programs\Python\Python310\lib\site-packages\django\db\utils.py", line 91, in __exit__
    raise dj_exc_value.with_traceback(traceback) from exc_value
  File "C:\Users\Windows 11\AppData\Local\Programs\Python\Python310\lib\site-packages\django\db\backends\utils.py", line 89, in _execute
    return self.cursor.execute(sql, params)
  File "C:\Users\Windows 11\AppData\Local\Programs\Python\Python310\lib\site-packages\django\db\backends\sqlite3\base.py", line 328, in execute
    return super().execute(query, params)
django.db.utils.IntegrityError: NOT NULL constraint failed: ThesisApp_person.status
"POST /update-status/ HTTP/1.1" 500 147502
Internal Server Error: /update-status/
Traceback (most recent call last):
  File "C:\Users\Windows 11\AppData\Local\Programs\Python\Python310\lib\site-packages\django\db\backends\utils.py", line 89, in _execute
    return self.cursor.execute(sql, params)
  File "C:\Users\Windows 11\AppData\Local\Programs\Python\Python310\lib\site-packages\django\db\backends\sqlite3\base.py", line 328, in execute
    return super().execute(query, params)
sqlite3.IntegrityError: NOT NULL constraint failed: ThesisApp_person.status

The above exception was the direct cause of the following exception:

Traceback (most recent call last):
  File "C:\Users\Windows 11\AppData\Local\Programs\Python\Python310\lib\site-packages\django\core\handlers\exception.py", line 55, in inner
    response = get_response(request)
  File "C:\Users\Windows 11\AppData\Local\Programs\Python\Python310\lib\site-packages\django\core\handlers\base.py", line 197, in _get_response
    response = wrapped_callback(request, *callback_args, **callback_kwargs)
  File "C:\Users\Windows 11\OneDrive\à´Ê¡ì·çÍ»\Coding\Python\Thesis Project\Thesis\ThesisApp\views.py", line 24, in update_status
    all_person.save()
  File "C:\Users\Windows 11\AppData\Local\Programs\Python\Python310\lib\site-packages\django\db\models\base.py", line 814, in save
    self.save_base(
  File "C:\Users\Windows 11\AppData\Local\Programs\Python\Python310\lib\site-packages\django\db\models\base.py", line 877, in save_base
    updated = self._save_table(
  File "C:\Users\Windows 11\AppData\Local\Programs\Python\Python310\lib\site-packages\django\db\models\base.py", line 990, in _save_table
    updated = self._do_update(
  File "C:\Users\Windows 11\AppData\Local\Programs\Python\Python310\lib\site-packages\django\db\models\base.py", line 1054, in _do_update
    return filtered._update(values) > 0
  File "C:\Users\Windows 11\AppData\Local\Programs\Python\Python310\lib\site-packages\django\db\models\query.py", line 1231, in _update
    return query.get_compiler(self.db).execute_sql(CURSOR)
  File "C:\Users\Windows 11\AppData\Local\Programs\Python\Python310\lib\site-packages\django\db\models\sql\compiler.py", line 1984, in execute_sql
    cursor = super().execute_sql(result_type)
  File "C:\Users\Windows 11\AppData\Local\Programs\Python\Python310\lib\site-packages\django\db\models\sql\compiler.py", line 1562, in execute_sql
    cursor.execute(sql, params)
  File "C:\Users\Windows 11\AppData\Local\Programs\Python\Python310\lib\site-packages\django\db\backends\utils.py", line 102, in execute
    return super().execute(sql, params)
  File "C:\Users\Windows 11\AppData\Local\Programs\Python\Python310\lib\site-packages\django\db\backends\utils.py", line 67, in execute
    return self._execute_with_wrappers(
  File "C:\Users\Windows 11\AppData\Local\Programs\Python\Python310\lib\site-packages\django\db\backends\utils.py", line 80, in _execute_with_wrappers
    return executor(sql, params, many, context)
  File "C:\Users\Windows 11\AppData\Local\Programs\Python\Python310\lib\site-packages\django\db\backends\utils.py", line 84, in _execute
    with self.db.wrap_database_errors:
  File "C:\Users\Windows 11\AppData\Local\Programs\Python\Python310\lib\site-packages\django\db\utils.py", line 91, in __exit__
    raise dj_exc_value.with_traceback(traceback) from exc_value
  File "C:\Users\Windows 11\AppData\Local\Programs\Python\Python310\lib\site-packages\django\db\backends\utils.py", line 89, in _execute
    return self.cursor.execute(sql, params)
  File "C:\Users\Windows 11\AppData\Local\Programs\Python\Python310\lib\site-packages\django\db\backends\sqlite3\base.py", line 328, in execute
    return super().execute(query, params)
django.db.utils.IntegrityError: NOT NULL constraint failed: ThesisApp_person.status
"POST /update-status/ HTTP/1.1" 500 147502
Internal Server Error: /update-status/
Traceback (most recent call last):
  File "C:\Users\Windows 11\AppData\Local\Programs\Python\Python310\lib\site-packages\django\db\backends\utils.py", line 89, in _execute
    return self.cursor.execute(sql, params)
  File "C:\Users\Windows 11\AppData\Local\Programs\Python\Python310\lib\site-packages\django\db\backends\sqlite3\base.py", line 328, in execute
    return super().execute(query, params)
sqlite3.IntegrityError: NOT NULL constraint failed: ThesisApp_person.status

The above exception was the direct cause of the following exception:

Traceback (most recent call last):
  File "C:\Users\Windows 11\AppData\Local\Programs\Python\Python310\lib\site-packages\django\core\handlers\exception.py", line 55, in inner
    response = get_response(request)
  File "C:\Users\Windows 11\AppData\Local\Programs\Python\Python310\lib\site-packages\django\core\handlers\base.py", line 197, in _get_response
    response = wrapped_callback(request, *callback_args, **callback_kwargs)
  File "C:\Users\Windows 11\OneDrive\à´Ê¡ì·çÍ»\Coding\Python\Thesis Project\Thesis\ThesisApp\views.py", line 24, in update_status
    all_person.save()
  File "C:\Users\Windows 11\AppData\Local\Programs\Python\Python310\lib\site-packages\django\db\models\base.py", line 814, in save
    self.save_base(
  File "C:\Users\Windows 11\AppData\Local\Programs\Python\Python310\lib\site-packages\django\db\models\base.py", line 877, in save_base
    updated = self._save_table(
  File "C:\Users\Windows 11\AppData\Local\Programs\Python\Python310\lib\site-packages\django\db\models\base.py", line 990, in _save_table
    updated = self._do_update(
  File "C:\Users\Windows 11\AppData\Local\Programs\Python\Python310\lib\site-packages\django\db\models\base.py", line 1054, in _do_update
    return filtered._update(values) > 0
  File "C:\Users\Windows 11\AppData\Local\Programs\Python\Python310\lib\site-packages\django\db\models\query.py", line 1231, in _update
    return query.get_compiler(self.db).execute_sql(CURSOR)
  File "C:\Users\Windows 11\AppData\Local\Programs\Python\Python310\lib\site-packages\django\db\models\sql\compiler.py", line 1984, in execute_sql
    cursor = super().execute_sql(result_type)
  File "C:\Users\Windows 11\AppData\Local\Programs\Python\Python310\lib\site-packages\django\db\models\sql\compiler.py", line 1562, in execute_sql
    cursor.execute(sql, params)
  File "C:\Users\Windows 11\AppData\Local\Programs\Python\Python310\lib\site-packages\django\db\backends\utils.py", line 102, in execute
    return super().execute(sql, params)
  File "C:\Users\Windows 11\AppData\Local\Programs\Python\Python310\lib\site-packages\django\db\backends\utils.py", line 67, in execute
    return self._execute_with_wrappers(
  File "C:\Users\Windows 11\AppData\Local\Programs\Python\Python310\lib\site-packages\django\db\backends\utils.py", line 80, in _execute_with_wrappers
    return executor(sql, params, many, context)
  File "C:\Users\Windows 11\AppData\Local\Programs\Python\Python310\lib\site-packages\django\db\backends\utils.py", line 84, in _execute
    with self.db.wrap_database_errors:
  File "C:\Users\Windows 11\AppData\Local\Programs\Python\Python310\lib\site-packages\django\db\utils.py", line 91, in __exit__
    raise dj_exc_value.with_traceback(traceback) from exc_value
  File "C:\Users\Windows 11\AppData\Local\Programs\Python\Python310\lib\site-packages\django\db\backends\utils.py", line 89, in _execute
    return self.cursor.execute(sql, params)
  File "C:\Users\Windows 11\AppData\Local\Programs\Python\Python310\lib\site-packages\django\db\backends\sqlite3\base.py", line 328, in execute
    return super().execute(query, params)
django.db.utils.IntegrityError: NOT NULL constraint failed: ThesisApp_person.status
"POST /update-status/ HTTP/1.1" 500 147502
Internal Server Error: /update-status/
Traceback (most recent call last):
  File "C:\Users\Windows 11\AppData\Local\Programs\Python\Python310\lib\site-packages\django\db\backends\utils.py", line 89, in _execute
    return self.cursor.execute(sql, params)
  File "C:\Users\Windows 11\AppData\Local\Programs\Python\Python310\lib\site-packages\django\db\backends\sqlite3\base.py", line 328, in execute
    return super().execute(query, params)
sqlite3.IntegrityError: NOT NULL constraint failed: ThesisApp_person.status

The above exception was the direct cause of the following exception:

Traceback (most recent call last):
  File "C:\Users\Windows 11\AppData\Local\Programs\Python\Python310\lib\site-packages\django\core\handlers\exception.py", line 55, in inner
    response = get_response(request)
  File "C:\Users\Windows 11\AppData\Local\Programs\Python\Python310\lib\site-packages\django\core\handlers\base.py", line 197, in _get_response
    response = wrapped_callback(request, *callback_args, **callback_kwargs)
  File "C:\Users\Windows 11\OneDrive\à´Ê¡ì·çÍ»\Coding\Python\Thesis Project\Thesis\ThesisApp\views.py", line 24, in update_status
    all_person.save()
  File "C:\Users\Windows 11\AppData\Local\Programs\Python\Python310\lib\site-packages\django\db\models\base.py", line 814, in save
    self.save_base(
  File "C:\Users\Windows 11\AppData\Local\Programs\Python\Python310\lib\site-packages\django\db\models\base.py", line 877, in save_base
    updated = self._save_table(
  File "C:\Users\Windows 11\AppData\Local\Programs\Python\Python310\lib\site-packages\django\db\models\base.py", line 990, in _save_table
    updated = self._do_update(
  File "C:\Users\Windows 11\AppData\Local\Programs\Python\Python310\lib\site-packages\django\db\models\base.py", line 1054, in _do_update
    return filtered._update(values) > 0
  File "C:\Users\Windows 11\AppData\Local\Programs\Python\Python310\lib\site-packages\django\db\models\query.py", line 1231, in _update
    return query.get_compiler(self.db).execute_sql(CURSOR)
  File "C:\Users\Windows 11\AppData\Local\Programs\Python\Python310\lib\site-packages\django\db\models\sql\compiler.py", line 1984, in execute_sql
    cursor = super().execute_sql(result_type)
  File "C:\Users\Windows 11\AppData\Local\Programs\Python\Python310\lib\site-packages\django\db\models\sql\compiler.py", line 1562, in execute_sql
    cursor.execute(sql, params)
  File "C:\Users\Windows 11\AppData\Local\Programs\Python\Python310\lib\site-packages\django\db\backends\utils.py", line 102, in execute
    return super().execute(sql, params)
  File "C:\Users\Windows 11\AppData\Local\Programs\Python\Python310\lib\site-packages\django\db\backends\utils.py", line 67, in execute
    return self._execute_with_wrappers(
  File "C:\Users\Windows 11\AppData\Local\Programs\Python\Python310\lib\site-packages\django\db\backends\utils.py", line 80, in _execute_with_wrappers
    return executor(sql, params, many, context)
  File "C:\Users\Windows 11\AppData\Local\Programs\Python\Python310\lib\site-packages\django\db\backends\utils.py", line 84, in _execute
    with self.db.wrap_database_errors:
  File "C:\Users\Windows 11\AppData\Local\Programs\Python\Python310\lib\site-packages\django\db\utils.py", line 91, in __exit__
    raise dj_exc_value.with_traceback(traceback) from exc_value
  File "C:\Users\Windows 11\AppData\Local\Programs\Python\Python310\lib\site-packages\django\db\backends\utils.py", line 89, in _execute
    return self.cursor.execute(sql, params)
  File "C:\Users\Windows 11\AppData\Local\Programs\Python\Python310\lib\site-packages\django\db\backends\sqlite3\base.py", line 328, in execute
    return super().execute(query, params)
django.db.utils.IntegrityError: NOT NULL constraint failed: ThesisApp_person.status
"POST /update-status/ HTTP/1.1" 500 147502
Internal Server Error: /update-status/
Traceback (most recent call last):
  File "C:\Users\Windows 11\AppData\Local\Programs\Python\Python310\lib\site-packages\django\db\backends\utils.py", line 89, in _execute
    return self.cursor.execute(sql, params)
  File "C:\Users\Windows 11\AppData\Local\Programs\Python\Python310\lib\site-packages\django\db\backends\sqlite3\base.py", line 328, in execute
    return super().execute(query, params)
sqlite3.IntegrityError: NOT NULL constraint failed: ThesisApp_person.status

The above exception was the direct cause of the following exception:

Traceback (most recent call last):
  File "C:\Users\Windows 11\AppData\Local\Programs\Python\Python310\lib\site-packages\django\core\handlers\exception.py", line 55, in inner
    response = get_response(request)
  File "C:\Users\Windows 11\AppData\Local\Programs\Python\Python310\lib\site-packages\django\core\handlers\base.py", line 197, in _get_response
    response = wrapped_callback(request, *callback_args, **callback_kwargs)
  File "C:\Users\Windows 11\OneDrive\à´Ê¡ì·çÍ»\Coding\Python\Thesis Project\Thesis\ThesisApp\views.py", line 24, in update_status
    all_person.save()
  File "C:\Users\Windows 11\AppData\Local\Programs\Python\Python310\lib\site-packages\django\db\models\base.py", line 814, in save
    self.save_base(
  File "C:\Users\Windows 11\AppData\Local\Programs\Python\Python310\lib\site-packages\django\db\models\base.py", line 877, in save_base
    updated = self._save_table(
  File "C:\Users\Windows 11\AppData\Local\Programs\Python\Python310\lib\site-packages\django\db\models\base.py", line 990, in _save_table
    updated = self._do_update(
  File "C:\Users\Windows 11\AppData\Local\Programs\Python\Python310\lib\site-packages\django\db\models\base.py", line 1054, in _do_update
    return filtered._update(values) > 0
  File "C:\Users\Windows 11\AppData\Local\Programs\Python\Python310\lib\site-packages\django\db\models\query.py", line 1231, in _update
    return query.get_compiler(self.db).execute_sql(CURSOR)
  File "C:\Users\Windows 11\AppData\Local\Programs\Python\Python310\lib\site-packages\django\db\models\sql\compiler.py", line 1984, in execute_sql
    cursor = super().execute_sql(result_type)
  File "C:\Users\Windows 11\AppData\Local\Programs\Python\Python310\lib\site-packages\django\db\models\sql\compiler.py", line 1562, in execute_sql
    cursor.execute(sql, params)
  File "C:\Users\Windows 11\AppData\Local\Programs\Python\Python310\lib\site-packages\django\db\backends\utils.py", line 102, in execute
    return super().execute(sql, params)
  File "C:\Users\Windows 11\AppData\Local\Programs\Python\Python310\lib\site-packages\django\db\backends\utils.py", line 67, in execute
    return self._execute_with_wrappers(
  File "C:\Users\Windows 11\AppData\Local\Programs\Python\Python310\lib\site-packages\django\db\backends\utils.py", line 80, in _execute_with_wrappers
    return executor(sql, params, many, context)
  File "C:\Users\Windows 11\AppData\Local\Programs\Python\Python310\lib\site-packages\django\db\backends\utils.py", line 84, in _execute
    with self.db.wrap_database_errors:
  File "C:\Users\Windows 11\AppData\Local\Programs\Python\Python310\lib\site-packages\django\db\utils.py", line 91, in __exit__
    raise dj_exc_value.with_traceback(traceback) from exc_value
  File "C:\Users\Windows 11\AppData\Local\Programs\Python\Python310\lib\site-packages\django\db\backends\utils.py", line 89, in _execute
    return self.cursor.execute(sql, params)
  File "C:\Users\Windows 11\AppData\Local\Programs\Python\Python310\lib\site-packages\django\db\backends\sqlite3\base.py", line 328, in execute
    return super().execute(query, params)
django.db.utils.IntegrityError: NOT NULL constraint failed: ThesisApp_person.status
"POST /update-status/ HTTP/1.1" 500 147502
Internal Server Error: /update-status/
Traceback (most recent call last):
  File "C:\Users\Windows 11\AppData\Local\Programs\Python\Python310\lib\site-packages\django\db\backends\utils.py", line 89, in _execute
    return self.cursor.execute(sql, params)
  File "C:\Users\Windows 11\AppData\Local\Programs\Python\Python310\lib\site-packages\django\db\backends\sqlite3\base.py", line 328, in execute
    return super().execute(query, params)
sqlite3.IntegrityError: NOT NULL constraint failed: ThesisApp_person.status

The above exception was the direct cause of the following exception:

Traceback (most recent call last):
  File "C:\Users\Windows 11\AppData\Local\Programs\Python\Python310\lib\site-packages\django\core\handlers\exception.py", line 55, in inner
    response = get_response(request)
  File "C:\Users\Windows 11\AppData\Local\Programs\Python\Python310\lib\site-packages\django\core\handlers\base.py", line 197, in _get_response
    response = wrapped_callback(request, *callback_args, **callback_kwargs)
  File "C:\Users\Windows 11\OneDrive\à´Ê¡ì·çÍ»\Coding\Python\Thesis Project\Thesis\ThesisApp\views.py", line 24, in update_status
    all_person.save()
  File "C:\Users\Windows 11\AppData\Local\Programs\Python\Python310\lib\site-packages\django\db\models\base.py", line 814, in save
    self.save_base(
  File "C:\Users\Windows 11\AppData\Local\Programs\Python\Python310\lib\site-packages\django\db\models\base.py", line 877, in save_base
    updated = self._save_table(
  File "C:\Users\Windows 11\AppData\Local\Programs\Python\Python310\lib\site-packages\django\db\models\base.py", line 990, in _save_table
    updated = self._do_update(
  File "C:\Users\Windows 11\AppData\Local\Programs\Python\Python310\lib\site-packages\django\db\models\base.py", line 1054, in _do_update
    return filtered._update(values) > 0
  File "C:\Users\Windows 11\AppData\Local\Programs\Python\Python310\lib\site-packages\django\db\models\query.py", line 1231, in _update
    return query.get_compiler(self.db).execute_sql(CURSOR)
  File "C:\Users\Windows 11\AppData\Local\Programs\Python\Python310\lib\site-packages\django\db\models\sql\compiler.py", line 1984, in execute_sql
    cursor = super().execute_sql(result_type)
  File "C:\Users\Windows 11\AppData\Local\Programs\Python\Python310\lib\site-packages\django\db\models\sql\compiler.py", line 1562, in execute_sql
    cursor.execute(sql, params)
  File "C:\Users\Windows 11\AppData\Local\Programs\Python\Python310\lib\site-packages\django\db\backends\utils.py", line 102, in execute
    return super().execute(sql, params)
  File "C:\Users\Windows 11\AppData\Local\Programs\Python\Python310\lib\site-packages\django\db\backends\utils.py", line 67, in execute
    return self._execute_with_wrappers(
  File "C:\Users\Windows 11\AppData\Local\Programs\Python\Python310\lib\site-packages\django\db\backends\utils.py", line 80, in _execute_with_wrappers
    return executor(sql, params, many, context)
  File "C:\Users\Windows 11\AppData\Local\Programs\Python\Python310\lib\site-packages\django\db\backends\utils.py", line 84, in _execute
    with self.db.wrap_database_errors:
  File "C:\Users\Windows 11\AppData\Local\Programs\Python\Python310\lib\site-packages\django\db\utils.py", line 91, in __exit__
    raise dj_exc_value.with_traceback(traceback) from exc_value
  File "C:\Users\Windows 11\AppData\Local\Programs\Python\Python310\lib\site-packages\django\db\backends\utils.py", line 89, in _execute
    return self.cursor.execute(sql, params)
  File "C:\Users\Windows 11\AppData\Local\Programs\Python\Python310\lib\site-packages\django\db\backends\sqlite3\base.py", line 328, in execute
    return super().execute(query, params)
django.db.utils.IntegrityError: NOT NULL constraint failed: ThesisApp_person.status
"POST /update-status/ HTTP/1.1" 500 147502
